<?xml version="1.0"?>
<robot xmlns:xacro="http://www.ros.org/wiki/xacro">
    
    <xacro:property name="effort" value="30.0" />
    <xacro:property name="velocity" value="10.0" />

    <xacro:macro name="default_inertia" params="mass">
        <inertial>
            <mass value="${mass}" />
            <inertia ixx="0.001" ixy="0.0" ixz="0.0"
                iyy="0.001" iyz="0.0"
                izz="0.001" />
        </inertial>
    </xacro:macro>

    <link name="world" />

    <link name="base_link">
        <visual>
            <origin xyz="-0.05 -0.05 0" rpy="0 0 0" />
            <geometry>
                <mesh filename="package://arduinobot_description/meshes/basement.STL"
                    scale="0.001 0.001 0.001" />
            </geometry>
            <material name="blue" />
        </visual>
        <collision>
            <origin xyz="-0.05 -0.05 0" rpy="0 0 0" />
            <geometry>
                <mesh filename="package://arduinobot_description/meshes/basement.STL"
                    scale="0.001 0.001 0.001" />
            </geometry>
        </collision>
        <xacro:default_inertia mass="0.1" />
    </link>

    <link name="base_plate">
        <visual>
            <origin xyz="-0.039 -0.039 -0.056" rpy="0 0 0" />
            <geometry>
                <mesh filename="package://arduinobot_description/meshes/base_plate.STL"
                    scale="0.001 0.001 0.001" />
            </geometry>
            <material name="orange" />
        </visual>
        <collision>
            <origin xyz="-0.039 -0.039 -0.056" rpy="0 0 0" />
            <geometry>
                <mesh filename="package://arduinobot_description/meshes/base_plate.STL"
                    scale="0.001 0.001 0.001" />
            </geometry>
        </collision>
        <xacro:default_inertia mass="0.01" />
    </link>

    <link name="forward_drive_arm">
        <visual>
            <origin xyz="0.019 0.006 -0.008" rpy="0 -${pi / 2.0} ${pi / 2.0}" />
            <geometry>
                <mesh filename="package://arduinobot_description/meshes/forward_drive_arm.STL"
                    scale="0.001 0.001 0.001" />
            </geometry>
            <material name="grey" />
        </visual>
        <collision>
            <origin xyz="0.019 0.006 -0.008" rpy="0 -${pi / 2.0} ${pi / 2.0}" />
            <geometry>
                <mesh filename="package://arduinobot_description/meshes/forward_drive_arm.STL"
                    scale="0.001 0.001 0.001" />
            </geometry>
        </collision>
        <xacro:default_inertia mass="0.01" />
    </link>

    <link name="horizontal_arm">
        <visual>
            <origin xyz="-0.003 -0.04 -0.006" rpy="${pi / 2.0} 0 ${pi / 2.0}" />
            <geometry>
                <mesh filename="package://arduinobot_description/meshes/horizontal_arm.STL"
                    scale="0.001 0.001 0.001" />
                <material name="grey" />
            </geometry>
            <material name="grey" />
        </visual>
        <collision>
            <origin xyz="-0.003 -0.04 -0.006" rpy="${pi / 2.0} 0 ${pi / 2.0}" />
            <geometry>
                <mesh filename="package://arduinobot_description/meshes/horizontal_arm.STL"
                    scale="0.001 0.001 0.001" />
                <material name="grey" />
            </geometry>
        </collision>
        <xacro:default_inertia mass="0.01" />
    </link>

    <link name="claw_support">
        <visual>
            <origin xyz="0 -0.005 -0.015" rpy="0 0 ${pi / 2.0}" />
            <geometry>
                <mesh filename="package://arduinobot_description/meshes/claw_support.STL"
                    scale="0.001 0.001 0.001" />
            </geometry>
            <material name="yellow" />
        </visual>
        <collision>
            <origin xyz="0 -0.005 -0.015" rpy="0 0 ${pi / 2.0}" />
            <geometry>
                <mesh filename="package://arduinobot_description/meshes/claw_support.STL"
                    scale="0.001 0.001 0.001" />
            </geometry>
        </collision>
        <xacro:default_inertia mass="0.005" />
    </link>

    <link name="gripper_right">
        <visual>
            <origin xyz="-0.01 0.05 -0.01" rpy="0 0 -${pi / 2.0}" />
            <geometry>
                <mesh filename="package://arduinobot_description/meshes/right_finger.STL"
                    scale="0.001 0.001 0.001" />
            </geometry>
            <material name="green" />
        </visual>
        <collision>
            <origin xyz="-0.01 0.05 -0.01" rpy="0 0 -${pi / 2.0}" />
            <geometry>
                <mesh filename="package://arduinobot_description/meshes/right_finger.STL"
                    scale="0.001 0.001 0.001" />
            </geometry>
        </collision>
        <xacro:default_inertia mass="0.001" />
    </link>

    <link name="gripper_left">
        <visual>
            <origin xyz="-0.004 0.05 -0.01" rpy="0 0 -${pi / 2.0}" />
            <geometry>
                <mesh filename="package://arduinobot_description/meshes/left_finger.STL"
                    scale="0.001 0.001 0.001" />
            </geometry>
            <material name="green" />
        </visual>
        <collision>
            <origin xyz="-0.004 0.05 -0.01" rpy="0 0 -${pi / 2.0}" />
            <geometry>
                <mesh filename="package://arduinobot_description/meshes/left_finger.STL"
                    scale="0.001 0.001 0.001" />
            </geometry>
        </collision>
        <xacro:default_inertia mass="0.001" />
    </link>


    <joint name="virtual_joint" type="fixed">
        <origin xyz="0 0 0" rpy="0 0 0" />
        <parent link="world" />
        <child link="base_link" />
    </joint>

    <joint name="joint_1" type="revolute">
        <origin xyz="0 0 0.0307" rpy="0 0 0" />
        <parent link="base_link" />
        <child link="base_plate" />
        <axis xyz="0 0 1" />
        <limit lower="-${pi / 2.0}" upper="${pi / 2.0}" effort="${effort}" velocity="${velocity}" />
    </joint>

    <joint name="joint_2" type="revolute">
        <origin xyz="-0.002 0 0.035" rpy="0 0 0" />
        <parent link="base_plate" />
        <child link="forward_drive_arm" />
        <axis xyz="1 0 0" />
        <limit lower="-${pi / 2.0}" upper="${pi / 2.0}" effort="${effort}" velocity="${velocity}" />
    </joint>

    <joint name="joint_3" type="revolute">
        <origin xyz="0 0 0.08" rpy="0 0 0" />
        <parent link="forward_drive_arm" />
        <child link="horizontal_arm" />
        <axis xyz="1 0 0" />
        <limit lower="-${pi / 2.0}" upper="${pi / 2.0}" effort="${effort}" velocity="${velocity}" />
    </joint>

    <joint name="horizontal_arm_to_claw_support" type="fixed">
        <origin xyz="0 0.082 0" rpy="0 0 0" />
        <parent link="horizontal_arm" />
        <child link="claw_support" />
    </joint>

    <joint name="joint_4" type="revolute">
        <origin xyz="-0.004 0.013 -0.01" rpy="0 0 0" />
        <parent link="claw_support" />
        <child link="gripper_right" />
        <axis xyz="0 0 1" />
        <limit lower="-${pi / 2.0}" upper="0" effort="${effort}" velocity="${velocity}" />
    </joint>

    <joint name="joint_5" type="revolute">
        <origin xyz="-0.022 0.013 -0.01" rpy="0 0 0" />
        <parent link="claw_support" />
        <child link="gripper_left" />
        <axis xyz="0 0 1" />
        <limit lower="0" upper="${pi / 2.0}" effort="${effort}" velocity="${velocity}" />
        <mimic joint="joint_4" multiplier="-1" />
    </joint>

</robot>